<?xml version="1.0"?>
<robot xmlns:xacro="http://www.ros.org/wiki/xacro" name="UR5">
	<xacro:macro name="DH_link"
		params="link_no a alpha d link_dia colour_r colour_g colour_b colour_a parent_link_name mass limit_min limit_max vel_max effort_max">

		<material name="mat_${link_no}">
			<color rgba="${colour_r} ${colour_g} ${colour_b} ${colour_a}" />
		</material>

		<link name="Link_${link_no}">
			<visual>
				<geometry>
					<cylinder length="${d}" radius="${link_dia}" />
				</geometry>
				<origin xyz="0  0 ${d*0.5}" rpy="0 0 0" />
				<material name="mat_${link_no}" />
			</visual>
			<xacro:unless value="${a==0}">
				<visual>
					<geometry>
						<cylinder length="${a}" radius="${link_dia}" />
					</geometry>
					<origin xyz="${a*0.5}  0 ${d}" rpy="0 1.57 0" />
					<material name="mat_${link_no}" />
				</visual>
			</xacro:unless>


			<collision>
				<geometry>
					<cylinder length="${d}" radius="${link_dia}" />
				</geometry>
				<origin xyz="0  0 ${d*0.5}" rpy="0 0 0" />
			</collision>


			<xacro:unless value="${a==0}">
				<collision>
					<geometry>
						<cylinder length="${a}" radius="${link_dia}" />
					</geometry>
					<origin xyz="${a*0.5}  0 ${d}" rpy="0 1.57 0" />
					<material name="mat_${link_no}" />
				</collision>
			</xacro:unless>

			<inertial>
				<mass value="${mass}" />
				<inertia ixx="0.4" ixy="0.0" ixz="0.0" iyy="0.4" iyz="0.0" izz="0.2" />
			</inertial>
		</link>

		<joint name="Joint_${link_no}" type="revolute">
			<parent link="${parent_link_name}" />
			<child link="Link_${link_no}" />
			<origin xyz="0 0.0 0" />
			<axis xyz="0 0 1" />
			<dynamics damping="0.0" friction="0.0" />
			<limit effort="${effort_max}" lower="${limit_min}" upper="${limit_max}"
				velocity="${vel_max}" />
		</joint>

		<link name="Link_${link_no}_child_frame">
		</link>

		<joint name="${link_no}_child_frame_joint" type="fixed">
			<origin xyz="${a}  0 ${d}" rpy="${alpha} 0 0" />
			<parent link="Link_${link_no}" />
			<child link="Link_${link_no}_child_frame" />
		</joint>

	</xacro:macro>


    <!-- Robot arm defination starts from here-->
    <!-- DH parameters are taken from this https://www.universal-robots.com/articles/ur/application-installation/dh-parameters-for-calculations-of-kinematics-and-dynamics/-->

	<link name="world" />

	<xacro:DH_link link_no="0" a="0" alpha="1.57" d="0.1273" link_dia=".05" colour_r="1"
		colour_g="0"
		colour_b="0" colour_a="0.7" parent_link_name="world" mass="1" limit_min="1.57"
		limit_max="-1.57" vel_max="10" effort_max="10" />

	<xacro:DH_link link_no="1" a="-0.612" alpha="0" d="0" link_dia=".05" colour_r="0" colour_g="1"
		colour_b="0" colour_a="0.7" parent_link_name="Link_0_child_frame" mass="1" limit_min="1.57"
		limit_max="-1.57" vel_max="10" effort_max="10" />

	<xacro:DH_link link_no="2" a="-0.5723" alpha="0" d="0" link_dia=".05" colour_r="0" colour_g="0"
		colour_b="1" colour_a="0.7" parent_link_name="Link_1_child_frame" mass="1" limit_min="1.57"
		limit_max="-1.57" vel_max="10" effort_max="10" />

	<xacro:DH_link link_no="3" a="0" alpha="1.57" d="0.163941" link_dia=".05" colour_r="0"
		colour_g="1"
		colour_b="1" colour_a="0.7" parent_link_name="Link_2_child_frame" mass="1" limit_min="1.57"
		limit_max="-1.57" vel_max="10" effort_max="10" />

	<xacro:DH_link link_no="4" a="0" alpha="-1.57" d="0.1157" link_dia=".05" colour_r="1"
		colour_g="1"
		colour_b="0" colour_a="0.7" parent_link_name="Link_3_child_frame" mass="1" limit_min="1.57"
		limit_max="-1.57" vel_max="10" effort_max="10" />

	<xacro:DH_link link_no="5" a="0" alpha="0" d="0.0922" link_dia=".05" colour_r="1" colour_g="1"
		colour_b="1" colour_a="0.7" parent_link_name="Link_4_child_frame" mass="1" limit_min="1.57"
		limit_max="-1.57" vel_max="10" effort_max="10" />


</robot>